Workbook

Sheet Summary
A1: Industry Name: Foods Pvt Ltd
A2: Location / Address: Uttar Pradesh
A3: Connectivity: Up to 11 kV - 11
A5: Calculation Base: | B5: Demand (MW)
A6: TOD | B6: Jul-26
A7: 10:00-19:00 | B7: 1.12
A8: 19:00-3:00 | B8: 1.12
A9: 3:00-5:00 | B9: 1.12
A10: 5:00-10:00 | B10: 1.12
A12: Savings | B12: Jul-26
A13: Billing Period | B13: - to -
A14: Cleared Units@Consumer bus 10:00-19:00 | B14: =IFERROR(VLOOKUP("10:00-19:00", 'Jul 2026'!$A$104:$G$107, 5, FALSE), 0)
A15: Cleared Units@Consumer bus 19:00-3:00 | B15: =IFERROR(VLOOKUP("19:00-3:00", 'Jul 2026'!$A$104:$G$107, 5, FALSE), 0)
A16: Cleared Units@Consumer bus 3:00-5:00 | B16: =IFERROR(VLOOKUP("3:00-5:00", 'Jul 2026'!$A$104:$G$107, 5, FALSE), 0)
A17: Cleared Units@Consumer bus 5:00-10:00 | B17: =IFERROR(VLOOKUP("5:00-10:00", 'Jul 2026'!$A$104:$G$107, 5, FALSE), 0)
A18: Total Cleared Units@Consumer bus | B18: =SUM(B14:B17)
A19: Total Consumption As per Ebill | B19: ='Jul 2026'!B108
A20: Cleared vs Actual consumption % | B20: =B18/B19
A21: Total Power Cost through Open Access | B21: ='Jul 2026'!B143
A22: Discom Cost | B22: ='Jul 2026'!B115
A23: Miscellaneous Charges | B23: 0
A25: Power Purchase Cost (Discom Only) | B25: =B22/B19
A26: Power Purchase Cost (With Prolt) | B26: =B21/B19
A27: Total Saving | B27: =B22-B21
A28: Saving/Unit | B28: =B27/B19
A29: Monthly NOC Fee | B29: ='Jul 2026'!B148
A30: IEX Registration Fee | B30: ='Jul 2026'!B149
A31: Consultancy Fee | B31: ='Jul 2026'!B150
A33: Margin Details | B33: Jul-26
A34: Trader Margin (Rs 0.02/kWh) | B34: ='Jul 2026'!B134
A35: Platform Fee (Rs 0.02/kWh) | B35: ='Jul 2026'!B151
A36: Value-Share for Energy Platform (15% of Saving) | B36: ='Jul 2026'!B152
A37: Total Amount | B37: =SUM(B29:B31)+B35+B36
A38: Probus Revenue /Unit | B38: =B37/B19
A40: Saving for your business | B40: =B27-B37
A41: Saving/Unit | B41: =B40/B19
A43: Average Monthly Saving | B43: =AVERAGE(B40:B40)
A44: Average Annual Saving | B44: =B43*12

Sheet Jul 2026
A1: Blockwise DAM Rates on IEX | B1: 1-Jul | E1: 2-Jul | H1: 3-Jul | K1: 4-Jul | N1: 5-Jul | Q1: 6-Jul | T1: 7-Jul | W1: 8-Jul | Z1: 9-Jul | AC1: 10-Jul | AF1: 11-Jul | AI1: 12-Jul | AL1: 13-Jul | AO1: 14-Jul | AR1: 15-Jul | AU1: 16-Jul | AX1: 17-Jul | BA1: 18-Jul | BD1: 19-Jul | BG1: 20-Jul | BJ1: 21-Jul | BM1: 22-Jul | BP1: 23-Jul | BS1: 24-Jul | BV1: 25-Jul | BY1: 26-Jul | CB1: 27-Jul | CE1: 28-Jul | CH1: 29-Jul | CK1: 30-Jul | CN1: 31-Jul
B2: Qty (MWh) | C2: Rate (Rs/kWh) | D2: Market | E2: Qty (MWh) | F2: Rate (Rs/kWh) | G2: Market | H2: Qty (MWh) | I2: Rate (Rs/kWh) | J2: Market | K2: Qty (MWh) | L2: Rate (Rs/kWh) | M2: Market | N2: Qty (MWh) | O2: Rate (Rs/kWh) | P2: Market | Q2: Qty (MWh) | R2: Rate (Rs/kWh) | S2: Market | T2: Qty (MWh) | U2: Rate (Rs/kWh) | V2: Market | W2: Qty (MWh) | X2: Rate (Rs/kWh) | Y2: Market | Z2: Qty (MWh) | AA2: Rate (Rs/kWh) | AB2: Market | AC2: Qty (MWh) | AD2: Rate (Rs/kWh) | AE2: Market | AF2: Qty (MWh) | AG2: Rate (Rs/kWh) | AH2: Market | AI2: Qty (MWh) | AJ2: Rate (Rs/kWh) | AK2: Market | AL2: Qty (MWh) | AM2: Rate (Rs/kWh) | AN2: Market | AO2: Qty (MWh) | AP2: Rate (Rs/kWh) | AQ2: Market | AR2: Qty (MWh) | AS2: Rate (Rs/kWh) | AT2: Market | AU2: Qty (MWh) | AV2: Rate (Rs/kWh) | AW2: Market | AX2: Qty (MWh) | AY2: Rate (Rs/kWh) | AZ2: Market | BA2: Qty (MWh) | BB2: Rate (Rs/kWh) | BC2: Market | BD2: Qty (MWh) | BE2: Rate (Rs/kWh) | BF2: Market | BG2: Qty (MWh) | BH2: Rate (Rs/kWh) | BI2: Market | BJ2: Qty (MWh) | BK2: Rate (Rs/kWh) | BL2: Market | BM2: Qty (MWh) | BN2: Rate (Rs/kWh) | BO2: Market | BP2: Qty (MWh) | BQ2: Rate (Rs/kWh) | BR2: Market | BS2: Qty (MWh) | BT2: Rate (Rs/kWh) | BU2: Market | BV2: Qty (MWh) | BW2: Rate (Rs/kWh) | BX2: Market | BY2: Qty (MWh) | BZ2: Rate (Rs/kWh) | CA2: Market | CB2: Qty (MWh) | CC2: Rate (Rs/kWh) | CD2: Market | CE2: Qty (MWh) | CF2: Rate (Rs/kWh) | CG2: Market | CH2: Qty (MWh) | CI2: Rate (Rs/kWh) | CJ2: Market | CK2: Qty (MWh) | CL2: Rate (Rs/kWh) | CM2: Market | CN2: Qty (MWh) | CO2: Rate (Rs/kWh) | CP2: Market
A3: 00:00 - 00:15 | B3: - | C3: - | D3: - | E3: - | F3: - | G3: - | H3: - | I3: - | J3: - | K3: 0 | L3: 4.45 | M3: DAM | N3: 0 | O3: 10 | P3: RTM | Q3: 0 | R3: 3.3 | S3: RTM | T3: 0 | U3: 4.2 | V3: DAM | W3: 0 | X3: 5 | Y3: DAM | Z3: 0 | AA3: 3.87 | AB3: RTM | AC3: 0 | AD3: 3.65 | AE3: RTM | AF3: 0 | AG3: 4.3 | AH3: RTM | AI3: 0 | AJ3: 5.4 | AK3: DAM | AL3: - | AM3: - | AN3: - | AO3: - | AP3: - | AQ3: - | AR3: - | AS3: - | AT3: - | AU3: - | AV3: - | AW3: - | AX3: - | AY3: - | AZ3: - | BA3: - | BB3: - | BC3: - | BD3: - | BE3: - | BF3: - | BG3: - | BH3: - | BI3: - | BJ3: - | BK3: - | BL3: - | BM3: 0 | BN3: 3.46 | BO3: RTM | BP3: 0 | BQ3: 4.1 | BR3: RTM | BS3: 0 | BT3: 3.41 | BU3: RTM | BV3: 0 | BW3: 5.48 | BX3: DAM | BY3: - | BZ3: - | CA3: - | CB3: - | CC3: - | CD3: - | CE3: - | CF3: - | CG3: - | CH3: 0 | CI3: 3.61 | CJ3: RTM | CK3: - | CL3: - | CM3: - | CN3: - | CO3: - | CP3: -
A4: 00:15 - 00:30 | B4: - | C4: - | D4: - | E4: - | F4: - | G4: - | H4: - | I4: - | J4: - | K4: 0 | L4: 4.36 | M4: DAM | N4: 0 | O4: 6.51 | P4: RTM | Q4: 0 | R4: 3.3 | S4: RTM | T4: 0 | U4: 4.01 | V4: DAM | W4: 0 | X4: 5 | Y4: DAM | Z4: 0 | AA4: 4.51 | AB4: RTM | AC4: 0 | AD4: 3.63 | AE4: RTM | AF4: 0 | AG4: 4.2 | AH4: RTM | AI4: 0 | AJ4: 4.76 | AK4: DAM | AL4: - | AM4: - | AN4: - | AO4: - | AP4: - | AQ4: - | AR4: - | AS4: - | AT4: - | AU4: - | AV4: - | AW4: - | AX4: - | AY4: - | AZ4: - | BA4: - | BB4: - | BC4: - | BD4: - | BE4: - | BF4: - | BG4: - | BH4: - | BI4: - | BJ4: - | BK4: - | BL4: - | BM4: 0 | BN4: 3.46 | BO4: RTM | BP4: 0 | BQ4: 3.95 | BR4: RTM | BS4: 0 | BT4: 3.4 | BU4: RTM | BV4: 0 | BW4: 4.85 | BX4: DAM | BY4: - | BZ4: - | CA4: - | CB4: - | CC4: - | CD4: - | CE4: - | CF4: - | CG4: - | CH4: 0 | CI4: 3.4 | CJ4: RTM | CK4: - | CL4: - | CM4: - | CN4: - | CO4: - | CP4: -
A5: 00:30 - 00:45 | B5: - | C5: - | D5: - | E5: 0 | F5: 3.76 | G5: RTM | H5: 0 | I5: 3.4 | J5: RTM | K5: 0 | L5: 4.2 | M5: DAM | N5: 0 | O5: 5.34 | P5: RTM | Q5: 0 | R5: 3.4 | S5: RTM | T5: 0 | U5: 4 | V5: DAM | W5: 0 | X5: 4.45 | Y5: DAM | Z5: 0 | AA5: 4.09 | AB5: RTM | AC5: 0 | AD5: 3.14 | AE5: RTM | AF5: 0 | AG5: 3.7 | AH5: RTM | AI5: 0 | AJ5: 4.43 | AK5: DAM | AL5: 0 | AM5: 4.34 | AN5: RTM | AO5: - | AP5: - | AQ5: - | AR5: - | AS5: - | AT5: - | AU5: - | AV5: - | AW5: - | AX5: - | AY5: - | AZ5: - | BA5: - | BB5: - | BC5: - | BD5: - | BE5: - | BF5: - | BG5: - | BH5: - | BI5: - | BJ5: - | BK5: - | BL5: - | BM5: 0 | BN5: 2.3 | BO5: RTM | BP5: 0 | BQ5: 3.4 | BR5: RTM | BS5: 0 | BT5: 3.31 | BU5: RTM | BV5: 0 | BW5: 3.75 | BX5: DAM | BY5: - | BZ5: - | CA5: - | CB5: - | CC5: - | CD5: - | CE5: - | CF5: - | CG5: - | CH5: 0 | CI5: 3.95 | CJ5: RTM | CK5: - | CL5: - | CM5: - | CN5: - | CO5: - | CP5: -
A6: 00:45 - 01:00 | B6: - | C6: - | D6: - | E6: 0 | F6: 3.5 | G6: RTM | H6: 0 | I6: 3.08 | J6: RTM | K6: 0 | L6: 4.2 | M6: DAM | N6: 0 | O6: 5.2 | P6: RTM | Q6: 0 | R6: 3.25 | S6: RTM | T6: 0 | U6: 3.81 | V6: DAM | W6: 0 | X6: 4.45 | Y6: DAM | Z6: 0 | AA6: 4.15 | AB6: RTM | AC6: 0 | AD6: 3.05 | AE6: RTM | AF6: 0 | AG6: 3.31 | AH6: RTM | AI6: 0 | AJ6: 4.19 | AK6: DAM | AL6: 0 | AM6: 3.77 | AN6: RTM | AO6: - | AP6: - | AQ6: - | AR6: - | AS6: - | AT6: - | AU6: - | AV6: - | AW6: - | AX6: - | AY6: - | AZ6: - | BA6: - | BB6: - | BC6: - | BD6: - | BE6: - | BF6: - | BG6: - | BH6: - | BI6: - | BJ6: 0 | BK6: 4.4 | BL6: RTM | BM6: 0.28 | BN6: 2 | BO6: RTM | BP6: 0 | BQ6: 3.31 | BR6: RTM | BS6: 0 | BT6: 3.17 | BU6: RTM | BV6: 0 | BW6: 3.68 | BX6: DAM | BY6: - | BZ6: - | CA6: - | CB6: - | CC6: - | CD6: - | CE6: - | CF6: - | CG6: - | CH6: 0 | CI6: 3.71 | CJ6: RTM | CK6: - | CL6: - | CM6: - | CN6: - | CO6: - | CP6: -
A7: 01:00 - 01:15 | B7: - | C7: - | D7: - | E7: 0 | F7: 3.85 | G7: RTM | H7: 0 | I7: 2.04 | J7: RTM | K7: 0 | L7: 3.4 | M7: DAM | N7: 0 | O7: 4.23 | P7: RTM | Q7: 0 | R7: 2.97 | S7: RTM | T7: 0 | U7: 3.61 | V7: DAM | W7: 0 | X7: 4.2 | Y7: DAM | Z7: 0 | AA7: 3.3 | AB7: RTM | AC7: 0 | AD7: 3.26 | AE7: RTM | AF7: 0 | AG7: 3.26 | AH7: RTM | AI7: 0 | AJ7: 3.95 | AK7: DAM | AL7: 0 | AM7: 3.77 | AN7: RTM | AO7: - | AP7: - | AQ7: - | AR7: - | AS7: - | AT7: - | AU7: - | AV7: - | AW7: - | AX7: - | AY7: - | AZ7: - | BA7: - | BB7: - | BC7: - | BD7: - | BE7: - | BF7: - | BG7: - | BH7: - | BI7: - | BJ7: 0 | BK7: 3.7 | BL7: RTM | BM7: 0 | BN7: 2 | BO7: RTM | BP7: 0 | BQ7: 3.16 | BR7: RTM | BS7: 0 | BT7: 2.5 | BU7: RTM | BV7: 0 | BW7: 3.41 | BX7: DAM | BY7: 0 | BZ7: 10 | CA7: DAM | CB7: - | CC7: - | CD7: - | CE7: - | CF7: - | CG7: - | CH7: 0 | CI7: 3.6 | CJ7: RTM | CK7: - | CL7: - | CM7: - | CN7: 0 | CO7: 4.1 | CP7: RTM
A8: 01:15 - 01:30 | B8: - | C8: - | D8: - | E8: 0 | F8: 3.6 | G8: RTM | H8: 0 | I8: 2.05 | J8: RTM | K8: 0 | L8: 3.33 | M8: DAM | N8: 0 | O8: 4 | P8: RTM | Q8: 0 | R8: 2.8 | S8: RTM | T8: 0 | U8: 3.4 | V8: DAM | W8: 0 | X8: 4.2 | Y8: DAM | Z8: 0 | AA8: 3.05 | AB8: RTM | AC8: 0 | AD8: 3.22 | AE8: RTM | AF8: 0 | AG8: 3.26 | AH8: RTM | AI8: 0 | AJ8: 3.78 | AK8: DAM | AL8: 0 | AM8: 3.6 | AN8: RTM | AO8: - | AP8: - | AQ8: - | AR8: - | AS8: - | AT8: - | AU8: - | AV8: - | AW8: - | AX8: - | AY8: - | AZ8: - | BA8: - | BB8: - | BC8: - | BD8: - | BE8: - | BF8: - | BG8: - | BH8: - | BI8: - | BJ8: 0 | BK8: 3.52 | BL8: RTM | BM8: 0 | BN8: 2 | BO8: RTM | BP8: 0 | BQ8: 2.62 | BR8: RTM | BS8: 0 | BT8: 2.19 | BU8: RTM | BV8: 0 | BW8: 3.3 | BX8: DAM | BY8: 0 | BZ8: 5.1 | CA8: DAM | CB8: - | CC8: - | CD8: - | CE8: 0 | CF8: 4.31 | CG8: RTM | CH8: 0 | CI8: 3.33 | CJ8: RTM | CK8: 0 | CL8: 4.04 | CM8: DAM | CN8: 0 | CO8: 3.6 | CP8: RTM
A9: 01:30 - 01:45 | B9: - | C9: - | D9: - | E9: 0 | F9: 2.5 | G9: RTM | H9: 0 | I9: 2.5 | J9: RTM | K9: 0 | L9: 3.15 | M9: DAM | N9: 0 | O9: 2.25 | P9: RTM | Q9: 0 | R9: 3.1 | S9: RTM | T9: 0 | U9: 3.61 | V9: DAM | W9: 0 | X9: 4.2 | Y9: DAM | Z9: 0 | AA9: 3 | AB9: RTM | AC9: 0 | AD9: 2.91 | AE9: RTM | AF9: 0 | AG9: 2.66 | AH9: RTM | AI9: 0 | AJ9: 3.61 | AK9: DAM | AL9: 0 | AM9: 2.55 | AN9: RTM | AO9: - | AP9: - | AQ9: - | AR9: - | AS9: - | AT9: - | AU9: - | AV9: - | AW9: - | AX9: - | AY9: - | AZ9: - | BA9: - | BB9: - | BC9: - | BD9: - | BE9: - | BF9: - | BG9: - | BH9: - | BI9: - | BJ9: 0 | BK9: 3.41 | BL9: RTM | BM9: 0 | BN9: 2.7 | BO9: RTM | BP9: 0 | BQ9: 2.95 | BR9: RTM | BS9: 0 | BT9: 2.84 | BU9: RTM | BV9: 0 | BW9: 3.16 | BX9: DAM | BY9: 0 | BZ9: 5 | CA9: DAM | CB9: 0 | CC9: 4.04 | CD9: RTM | CE9: 0 | CF9: 4.65 | CG9: RTM | CH9: 0 | CI9: 3.3 | CJ9: RTM | CK9: 0 | CL9: 3.83 | CM9: DAM | CN9: 0 | CO9: 3 | CP9: RTM
A10: 01:45 - 02:00 | B10: - | C10: - | D10: - | E10: 0.28 | F10: 1.8 | G10: RTM | H10: 0 | I10: 2.68 | J10: RTM | K10: 0 | L10: 3.39 | M10: DAM | N10: 0 | O10: 2.04 | P10: RTM | Q10: 0 | R10: 3.1 | S10: RTM | T10: 0 | U10: 3.46 | V10: DAM | W10: 0 | X10: 4.03 | Y10: DAM | Z10: 0 | AA10: 3 | AB10: RTM | AC10: 0 | AD10: 2.62 | AE10: RTM | AF10: 0 | AG10: 2.4 | AH10: RTM | AI10: 0 | AJ10: 3.61 | AK10: DAM | AL10: 0 | AM10: 2.66 | AN10: RTM | AO10: - | AP10: - | AQ10: - | AR10: - | AS10: - | AT10: - | AU10: - | AV10: - | AW10: - | AX10: - | AY10: - | AZ10: - | BA10: - | BB10: - | BC10: - | BD10: - | BE10: - | BF10: - | BG10: - | BH10: - | BI10: - | BJ10: 0 | BK10: 3.4 | BL10: RTM | BM10: 0 | BN10: 2.69 | BO10: RTM | BP10: 0 | BQ10: 3.14 | BR10: RTM | BS10: 0 | BT10: 2.84 | BU10: RTM | BV10: 0 | BW10: 3.21 | BX10: DAM | BY10: 0 | BZ10: 3.95 | CA10: DAM | CB10: 0 | CC10: 4 | CD10: RTM | CE10: 0 | CF10: 4.75 | CG10: RTM | CH10: 0 | CI10: 3.3 | CJ10: RTM | CK10: 0 | CL10: 3.68 | CM10: DAM | CN10: 0 | CO10: 3.1 | CP10: RTM
A11: 02:00 - 02:15 | B11: - | C11: - | D11: - | E11: 0.28 | F11: 1 | G11: RTM | H11: 0 | I11: 3 | J11: RTM | K11: 0 | L11: 3.11 | M11: DAM | N11: 0 | O11: 3 | P11: RTM | Q11: 0 | R11: 2.62 | S11: RTM | T11: 0 | U11: 3.31 | V11: DAM | W11: 0 | X11: 3.6 | Y11: DAM | Z11: 0 | AA11: 3.5 | AB11: RTM | AC11: 0 | AD11: 2.42 | AE11: RTM | AF11: 0 | AG11: 2.62 | AH11: RTM | AI11: 0 | AJ11: 3.5 | AK11: DAM | AL11: 0 | AM11: 4 | AN11: RTM | AO11: 0 | AP11: 10 | AQ11: DAM | AR11: - | AS11: - | AT11: - | AU11: - | AV11: - | AW11: - | AX11: - | AY11: - | AZ11: - | BA11: - | BB11: - | BC11: - | BD11: - | BE11: - | BF11: - | BG11: - | BH11: - | BI11: - | BJ11: 0 | BK11: 3.4 | BL11: RTM | BM11: 0 | BN11: 3 | BO11: RTM | BP11: 0 | BQ11: 3.22 | BR11: RTM | BS11: 0 | BT11: 2.77 | BU11: RTM | BV11: 0 | BW11: 3.11 | BX11: DAM | BY11: 0 | BZ11: 3.5 | CA11: DAM | CB11: 0 | CC11: 3.71 | CD11: RTM | CE11: 0 | CF11: 4.86 | CG11: RTM | CH11: 0 | CI11: 2.62 | CJ11: RTM | CK11: 0 | CL11: 3.63 | CM11: DAM | CN11: 0 | CO11: 3.63 | CP11: RTM
A12: 02:15 - 02:30 | B12: - | C12: - | D12: - | E12: 0.28 | F12: 1 | G12: RTM | H12: 0 | I12: 3 | J12: RTM | K12: 0 | L12: 3.04 | M12: DAM | N12: 0 | O12: 3 | P12: RTM | Q12: 0 | R12: 2.56 | S12: RTM | T12: 0 | U12: 3.23 | V12: DAM | W12: 0 | X12: 3.46 | Y12: DAM | Z12: 0 | AA12: 3.41 | AB12: RTM | AC12: 0 | AD12: 2.25 | AE12: RTM | AF12: 0 | AG12: 2.62 | AH12: RTM | AI12: 0 | AJ12: 3.5 | AK12: DAM | AL12: 0 | AM12: 4.09 | AN12: RTM | AO12: 0 | AP12: 10 | AQ12: DAM | AR12: - | AS12: - | AT12: - | AU12: - | AV12: - | AW12: - | AX12: - | AY12: - | AZ12: - | BA12: - | BB12: - | BC12: - | BD12: - | BE12: - | BF12: - | BG12: - | BH12: - | BI12: - | BJ12: 0 | BK12: 3.31 | BL12: RTM | BM12: 0 | BN12: 3 | BO12: RTM | BP12: 0 | BQ12: 3.18 | BR12: RTM | BS12: 0 | BT12: 2.77 | BU12: RTM | BV12: 0 | BW12: 3.06 | BX12: DAM | BY12: 0 | BZ12: 3.41 | CA12: DAM | CB12: 0 | CC12: 3.9 | CD12: RTM | CE12: 0 | CF12: 4.75 | CG12: RTM | CH12: 0 | CI12: 3 | CJ12: RTM | CK12: 0 | CL12: 3.68 | CM12: DAM | CN12: 0 | CO12: 3.85 | CP12: RTM
A13: 02:30 - 02:45 | B13: 0 | C13: 4 | D13: RTM | E13: 0.28 | F13: 0.4 | G13: RTM | H13: 0 | I13: 3.25 | J13: RTM | K13: 0 | L13: 3.13 | M13: DAM | N13: 0 | O13: 3.34 | P13: RTM | Q13: 0 | R13: 2.62 | S13: RTM | T13: 0 | U13: 3.1 | V13: DAM | W13: 0 | X13: 3.61 | Y13: DAM | Z13: 0 | AA13: 3.59 | AB13: RTM | AC13: 0 | AD13: 2.61 | AE13: RTM | AF13: 0 | AG13: 2.62 | AH13: RTM | AI13: 0 | AJ13: 3.61 | AK13: DAM | AL13: 0 | AM13: 3.78 | AN13: RTM | AO13: 0 | AP13: 10 | AQ13: DAM | AR13: - | AS13: - | AT13: - | AU13: - | AV13: - | AW13: - | AX13: - | AY13: - | AZ13: - | BA13: - | BB13: - | BC13: - | BD13: - | BE13: - | BF13: - | BG13: - | BH13: - | BI13: - | BJ13: 0 | BK13: 3.3 | BL13: RTM | BM13: 0 | BN13: 3.05 | BO13: RTM | BP13: 0 | BQ13: 2.6 | BR13: RTM | BS13: 0 | BT13: 2.54 | BU13: RTM | BV13: 0 | BW13: 3 | BX13: DAM | BY13: 0 | BZ13: 3.3 | CA13: DAM | CB13: 0 | CC13: 3.69 | CD13: RTM | CE13: 0 | CF13: 4.55 | CG13: RTM | CH13: 0 | CI13: 3.2 | CJ13: RTM | CK13: 0 | CL13: 3.68 | CM13: DAM | CN13: 0 | CO13: 3.95 | CP13: RTM
A14: 02:45 - 03:00 | B14: 0 | C14: 3.9 | D14: RTM | E14: 0.28 | F14: 1 | G14: RTM | H14: 0 | I14: 3.25 | J14: RTM | K14: 0 | L14: 3.11 | M14: DAM | N14: 0 | O14: 3.4 | P14: RTM | Q14: 0 | R14: 2.56 | S14: RTM | T14: 0 | U14: 3.2 | V14: DAM | W14: 0 | X14: 3.61 | Y14: DAM | Z14: 0 | AA14: 3.6 | AB14: RTM | AC14: 0 | AD14: 2.62 | AE14: RTM | AF14: 0 | AG14: 2.8 | AH14: RTM | AI14: 0 | AJ14: 3.61 | AK14: DAM | AL14: 0 | AM14: 3.85 | AN14: RTM | AO14: 0 | AP14: 10 | AQ14: DAM | AR14: - | AS14: - | AT14: - | AU14: - | AV14: - | AW14: - | AX14: - | AY14: - | AZ14: - | BA14: - | BB14: - | BC14: - | BD14: - | BE14: - | BF14: - | BG14: - | BH14: - | BI14: - | BJ14: 0 | BK14: 3.19 | BL14: RTM | BM14: 0 | BN14: 3 | BO14: RTM | BP14: 0 | BQ14: 2.52 | BR14: RTM | BS14: 0 | BT14: 3 | BU14: RTM | BV14: 0 | BW14: 3 | BX14: DAM | BY14: 0 | BZ14: 3.26 | CA14: DAM | CB14: 0 | CC14: 3.64 | CD14: RTM | CE14: 0 | CF14: 4.62 | CG14: RTM | CH14: 0 | CI14: 3.26 | CJ14: RTM | CK14: 0 | CL14: 3.68 | CM14: DAM | CN14: 0 | CO14: 3.95 | CP14: RTM
A15: 03:00 - 03:15 | B15: 0 | C15: 2.79 | D15: RTM | E15: 0.28 | F15: 1.54 | G15: RTM | H15: 0 | I15: 2.04 | J15: RTM | K15: 0 | L15: 3.25 | M15: DAM | N15: 0 | O15: 2.62 | P15: RTM | Q15: 0.28 | R15: 0.5 | S15: RTM | T15: 0 | U15: 3.23 | V15: DAM | W15: 0 | X15: 3.61 | Y15: DAM | Z15: 0 | AA15: 3.3 | AB15: RTM | AC15: 0 | AD15: 2.51 | AE15: RTM | AF15: 0 | AG15: 2.5 | AH15: RTM | AI15: 0 | AJ15: 3.57 | AK15: DAM | AL15: 0 | AM15: 3.02 | AN15: RTM | AO15: - | AP15: - | AQ15: - | AR15: - | AS15: - | AT15: - | AU15: - | AV15: - | AW15: - | AX15: - | AY15: - | AZ15: - | BA15: - | BB15: - | BC15: - | BD15: - | BE15: - | BF15: - | BG15: - | BH15: - | BI15: - | BJ15: 0 | BK15: 3.19 | BL15: RTM | BM15: 0 | BN15: 2.19 | BO15: RTM | BP15: 0.28 | BQ15: 1.94 | BR15: RTM | BS15: 0 | BT15: 2.42 | BU15: RTM | BV15: 0 | BW15: 3 | BX15: DAM | BY15: 0 | BZ15: 3.12 | CA15: DAM | CB15: 0 | CC15: 3.3 | CD15: RTM | CE15: 0 | CF15: 3.6 | CG15: RTM | CH15: 0 | CI15: 2.5 | CJ15: RTM | CK15: 0 | CL15: 3.6 | CM15: DAM | CN15: 0 | CO15: 3.6 | CP15: RTM
A16: 03:15 - 03:30 | B16: 0 | C16: 2.79 | D16: RTM | E16: 0.28 | F16: 1.4 | G16: RTM | H16: 0 | I16: 2.19 | J16: RTM | K16: 0 | L16: 3.25 | M16: DAM | N16: 0 | O16: 2.5 | P16: RTM | Q16: 0.28 | R16: 1.2 | S16: RTM | T16: 0 | U16: 3.23 | V16: DAM | W16: 0 | X16: 3.61 | Y16: DAM | Z16: 0 | AA16: 2.62 | AB16: RTM | AC16: 0 | AD16: 2.62 | AE16: RTM | AF16: 0 | AG16: 2.62 | AH16: RTM | AI16: 0 | AJ16: 3.61 | AK16: DAM | AL16: 0 | AM16: 3.15 | AN16: RTM | AO16: - | AP16: - | AQ16: - | AR16: - | AS16: - | AT16: - | AU16: - | AV16: - | AW16: - | AX16: - | AY16: - | AZ16: - | BA16: - | BB16: - | BC16: - | BD16: - | BE16: - | BF16: - | BG16: - | BH16: - | BI16: - | BJ16: 0 | BK16: 3.03 | BL16: RTM | BM16: 0 | BN16: 2.18 | BO16: RTM | BP16: 0 | BQ16: 2.04 | BR16: RTM | BS16: 0 | BT16: 2.61 | BU16: RTM | BV16: 0 | BW16: 3 | BX16: DAM | BY16: 0 | BZ16: 3.08 | CA16: DAM | CB16: 0 | CC16: 3.28 | CD16: RTM | CE16: 0 | CF16: 3.5 | CG16: RTM | CH16: 0 | CI16: 2.86 | CJ16: RTM | CK16: 0 | CL16: 3.5 | CM16: DAM | CN16: 0 | CO16: 3.4 | CP16: RTM
A17: 03:30 - 03:45 | B17: 0 | C17: 3.35 | D17: RTM | E17: 0 | F17: 2.53 | G17: RTM | H17: 0 | I17: 2.49 | J17: RTM | K17: 0 | L17: 3.25 | M17: DAM | N17: 0 | O17: 2.71 | P17: RTM | Q17: 0.28 | R17: 1.91 | S17: RTM | T17: 0 | U17: 3.23 | V17: DAM | W17: 0 | X17: 3.63 | Y17: DAM | Z17: 0 | AA17: 2.95 | AB17: RTM | AC17: 0 | AD17: 2.62 | AE17: RTM | AF17: 0 | AG17: 2.19 | AH17: RTM | AI17: 0 | AJ17: 3.61 | AK17: DAM | AL17: 0 | AM17: 3.3 | AN17: RTM | AO17: - | AP17: - | AQ17: - | AR17: - | AS17: - | AT17: - | AU17: - | AV17: - | AW17: - | AX17: - | AY17: - | AZ17: - | BA17: - | BB17: - | BC17: - | BD17: - | BE17: - | BF17: - | BG17: - | BH17: - | BI17: - | BJ17: 0 | BK17: 3 | BL17: RTM | BM17: 0 | BN17: 2 | BO17: RTM | BP17: 0 | BQ17: 2.52 | BR17: RTM | BS17: 0.28 | BT17: 1 | BU17: RTM | BV17: 0 | BW17: 2.91 | BX17: DAM | BY17: 0 | BZ17: 3.03 | CA17: DAM | CB17: 0 | CC17: 3.4 | CD17: RTM | CE17: 0 | CF17: 3.34 | CG17: RTM | CH17: 0 | CI17: 3.3 | CJ17: RTM | CK17: 0 | CL17: 3.4 | CM17: DAM | CN17: 0 | CO17: 3.16 | CP17: RTM
A18: 03:45 - 04:00 | B18: 0 | C18: 3.3 | D18: RTM | E18: 0 | F18: 2.5 | G18: RTM | H18: 0 | I18: 2.5 | J18: RTM | K18: 0 | L18: 3.4 | M18: DAM | N18: 0 | O18: 2.5 | P18: RTM | Q18: 0.28 | R18: 2 | S18: RTM | T18: 0 | U18: 3.23 | V18: DAM | W18: 0 | X18: 3.61 | Y18: DAM | Z18: 0 | AA18: 2.48 | AB18: RTM | AC18: 0 | AD18: 2.51 | AE18: RTM | AF18: 0 | AG18: 2.19 | AH18: RTM | AI18: 0 | AJ18: 3.61 | AK18: DAM | AL18: 0 | AM18: 3.1 | AN18: RTM | AO18: - | AP18: - | AQ18: - | AR18: - | AS18: - | AT18: - | AU18: - | AV18: - | AW18: - | AX18: - | AY18: - | AZ18: - | BA18: - | BB18: - | BC18: - | BD18: - | BE18: - | BF18: - | BG18: - | BH18: - | BI18: - | BJ18: 0 | BK18: 3 | BL18: RTM | BM18: 0.28 | BN18: 1.8 | BO18: RTM | BP18: 0 | BQ18: 2.55 | BR18: RTM | BS18: 0.28 | BT18: 0.11 | BU18: RTM | BV18: 0 | BW18: 2.91 | BX18: DAM | BY18: 0 | BZ18: 3.03 | CA18: DAM | CB18: 0 | CC18: 3.3 | CD18: RTM | CE18: 0 | CF18: 3.3 | CG18: RTM | CH18: 0 | CI18: 3.15 | CJ18: RTM | CK18: 0 | CL18: 3.36 | CM18: DAM | CN18: 0 | CO18: 2.04 | CP18: RTM
A19: 04:00 - 04:15 | B19: 0 | C19: 3.57 | D19: RTM | E19: 0.28 | F19: 0.5 | G19: RTM | H19: 0 | I19: 3 | J19: RTM | K19: 0 | L19: 3.4 | M19: DAM | N19: 0 | O19: 3.22 | P19: RTM | Q19: 0 | R19: 2.18 | S19: RTM | T19: 0 | U19: 3.26 | V19: DAM | W19: 0 | X19: 3.61 | Y19: DAM | Z19: 0 | AA19: 2.76 | AB19: RTM | AC19: 0 | AD19: 3 | AE19: RTM | AF19: 0 | AG19: 2.5 | AH19: RTM | AI19: 0 | AJ19: 3.61 | AK19: DAM | AL19: 0 | AM19: 3.36 | AN19: RTM | AO19: - | AP19: - | AQ19: - | AR19: - | AS19: - | AT19: - | AU19: - | AV19: - | AW19: - | AX19: - | AY19: - | AZ19: - | BA19: - | BB19: - | BC19: - | BD19: - | BE19: - | BF19: - | BG19: - | BH19: - | BI19: - | BJ19: 0 | BK19: 2.91 | BL19: RTM | BM19: 0 | BN19: 2.01 | BO19: RTM | BP19: 0 | BQ19: 2.52 | BR19: RTM | BS19: 0 | BT19: 2.5 | BU19: RTM | BV19: 0 | BW19: 2.9 | BX19: DAM | BY19: 0 | BZ19: 3.12 | CA19: DAM | CB19: 0 | CC19: 3.51 | CD19: RTM | CE19: 0 | CF19: 3.38 | CG19: RTM | CH19: 0 | CI19: 3.2 | CJ19: RTM | CK19: 0 | CL19: 3.3 | CM19: DAM | CN19: 0 | CO19: 2.6 | CP19: RTM
A20: 04:15 - 04:30 | B20: 0 | C20: 3.55 | D20: RTM | E20: 0.28 | F20: 0.5 | G20: RTM | H20: 0 | I20: 3 | J20: RTM | K20: 0 | L20: 3.5 | M20: DAM | N20: 0 | O20: 3.21 | P20: RTM | Q20: 0 | R20: 2.5 | S20: RTM | T20: 0 | U20: 3.28 | V20: DAM | W20: 0 | X20: 3.63 | Y20: DAM | Z20: 0 | AA20: 3.1 | AB20: RTM | AC20: 0 | AD20: 3 | AE20: RTM | AF20: 0 | AG20: 2.62 | AH20: RTM | AI20: 0 | AJ20: 3.61 | AK20: DAM | AL20: 0 | AM20: 3.5 | AN20: RTM | AO20: - | AP20: - | AQ20: - | AR20: - | AS20: - | AT20: - | AU20: - | AV20: - | AW20: - | AX20: - | AY20: - | AZ20: - | BA20: - | BB20: - | BC20: - | BD20: - | BE20: - | BF20: - | BG20: - | BH20: - | BI20: - | BJ20: 0 | BK20: 3 | BL20: RTM | BM20: 0 | BN20: 2.18 | BO20: RTM | BP20: 0 | BQ20: 2.54 | BR20: RTM | BS20: 0 | BT20: 2.59 | BU20: RTM | BV20: 0 | BW20: 2.9 | BX20: DAM | BY20: 0 | BZ20: 3.12 | CA20: DAM | CB20: 0 | CC20: 3.64 | CD20: RTM | CE20: 0 | CF20: 3.5 | CG20: RTM | CH20: 0 | CI20: 3.22 | CJ20: RTM | CK20: 0 | CL20: 3.26 | CM20: DAM | CN20: 0 | CO20: 2.85 | CP20: RTM
A21: 04:30 - 04:45 | B21: 0 | C21: 3.6 | D21: RTM | E21: 0.28 | F21: 0.1 | G21: RTM | H21: 0 | I21: 3.29 | J21: RTM | K21: 0 | L21: 3.61 | M21: DAM | N21: 0 | O21: 3.31 | P21: RTM | Q21: 0 | R21: 2.52 | S21: RTM | T21: 0 | U21: 3.28 | V21: DAM | W21: 0 | X21: 3.63 | Y21: DAM | Z21: 0 | AA21: 2.8 | AB21: RTM | AC21: 0 | AD21: 3.1 | AE21: RTM | AF21: 0 | AG21: 2.58 | AH21: RTM | AI21: 0 | AJ21: 3.61 | AK21: DAM | AL21: - | AM21: - | AN21: - | AO21: - | AP21: - | AQ21: - | AR21: - | AS21: - | AT21: - | AU21: - | AV21: - | AW21: - | AX21: - | AY21: - | AZ21: - | BA21: - | BB21: - | BC21: - | BD21: - | BE21: - | BF21: - | BG21: - | BH21: - | BI21: - | BJ21: 0 | BK21: 2.89 | BL21: RTM | BM21: 0 | BN21: 2.78 | BO21: RTM | BP21: 0 | BQ21: 2.58 | BR21: RTM | BS21: 0 | BT21: 2.04 | BU21: RTM | BV21: 0 | BW21: 2.89 | BX21: DAM | BY21: 0 | BZ21: 3.08 | CA21: DAM | CB21: 0 | CC21: 3.63 | CD21: RTM | CE21: 0 | CF21: 3.55 | CG21: RTM | CH21: 0 | CI21: 2.3 | CJ21: RTM | CK21: 0 | CL21: 3.26 | CM21: DAM | CN21: 0 | CO21: 3.25 | CP21: RTM
A22: 04:45 - 05:00 | B22: 0 | C22: 3.5 | D22: RTM | E22: 0.28 | F22: 0.8 | G22: RTM | H22: 0 | I22: 3.29 | J22: RTM | K22: 0 | L22: 3.61 | M22: DAM | N22: 0 | O22: 3.26 | P22: RTM | Q22: 0 | R22: 2.54 | S22: RTM | T22: 0 | U22: 3.28 | V22: DAM | W22: 0 | X22: 3.74 | Y22: DAM | Z22: 0 | AA22: 3.01 | AB22: RTM | AC22: 0 | AD22: 3 | AE22: RTM | AF22: 0 | AG22: 2.62 | AH22: RTM | AI22: 0 | AJ22: 3.63 | AK22: DAM | AL22: - | AM22: - | AN22: - | AO22: - | AP22: - | AQ22: - | AR22: - | AS22: - | AT22: - | AU22: - | AV22: - | AW22: - | AX22: - | AY22: - | AZ22: - | BA22: - | BB22: - | BC22: - | BD22: - | BE22: - | BF22: - | BG22: - | BH22: - | BI22: - | BJ22: 0 | BK22: 2.89 | BL22: RTM | BM22: 0 | BN22: 3 | BO22: RTM | BP22: 0 | BQ22: 2.54 | BR22: RTM | BS22: 0 | BT22: 2 | BU22: RTM | BV22: 0 | BW22: 3 | BX22: DAM | BY22: 0 | BZ22: 3.34 | CA22: DAM | CB22: - | CC22: - | CD22: - | CE22: 0 | CF22: 3.65 | CG22: RTM | CH22: 0 | CI22: 2.62 | CJ22: RTM | CK22: 0 | CL22: 3.5 | CM22: DAM | CN22: 0 | CO22: 3.31 | CP22: RTM
A23: 05:00 - 05:15 | B23: - | C23: - | D23: - | E23: 0 | F23: 2.49 | G23: RTM | H23: - | I23: - | J23: - | K23: 0 | L23: 3.61 | M23: DAM | N23: 0 | O23: 2.55 | P23: RTM | Q23: 0 | R23: 2.5 | S23: RTM | T23: - | U23: - | V23: - | W23: 0 | X23: 3.61 | Y23: DAM | Z23: - | AA23: - | AB23: - | AC23: - | AD23: - | AE23: - | AF23: - | AG23: - | AH23: - | AI23: - | AJ23: - | AK23: - | AL23: - | AM23: - | AN23: - | AO23: - | AP23: - | AQ23: - | AR23: - | AS23: - | AT23: - | AU23: - | AV23: - | AW23: - | AX23: - | AY23: - | AZ23: - | BA23: - | BB23: - | BC23: - | BD23: - | BE23: - | BF23: - | BG23: - | BH23: - | BI23: - | BJ23: - | BK23: - | BL23: - | BM23: - | BN23: - | BO23: - | BP23: - | BQ23: - | BR23: - | BS23: 0 | BT23: 2.56 | BU23: RTM | BV23: - | BW23: - | BX23: - | BY23: - | BZ23: - | CA23: - | CB23: - | CC23: - | CD23: - | CE23: - | CF23: - | CG23: - | CH23: - | CI23: - | CJ23: - | CK23: - | CL23: - | CM23: - | CN23: - | CO23: - | CP23: -
A24: 05:15 - 05:30 | B24: - | C24: - | D24: - | E24: 0 | F24: 2.53 | G24: RTM | H24: - | I24: - | J24: - | K24: 0 | L24: 3.76 | M24: DAM | N24: 0 | O24: 2.5 | P24: RTM | Q24: 0 | R24: 2.56 | S24: RTM | T24: - | U24: - | V24: - | W24: - | X24: - | Y24: - | Z24: - | AA24: - | AB24: - | AC24: - | AD24: - | AE24: - | AF24: - | AG24: - | AH24: - | AI24: - | AJ24: - | AK24: - | AL24: - | AM24: - | AN24: - | AO24: - | AP24: - | AQ24: - | AR24: - | AS24: - | AT24: - | AU24: - | AV24: - | AW24: - | AX24: - | AY24: - | AZ24: - | BA24: - | BB24: - | BC24: - | BD24: - | BE24: - | BF24: - | BG24: - | BH24: - | BI24: - | BJ24: - | BK24: - | BL24: - | BM24: - | BN24: - | BO24: - | BP24: - | BQ24: - | BR24: - | BS24: 0 | BT24: 2.65 | BU24: RTM | BV24: - | BW24: - | BX24: - | BY24: - | BZ24: - | CA24: - | CB24: - | CC24: - | CD24: - | CE24: - | CF24: - | CG24: - | CH24: - | CI24: - | CJ24: - | CK24: - | CL24: - | CM24: - | CN24: - | CO24: - | CP24: -
A25: 05:30 - 05:45 | B25: - | C25: - | D25: - | E25: 0 | F25: 2.62 | G25: RTM | H25: - | I25: - | J25: - | K25: - | L25: - | M25: - | N25: - | O25: - | P25: - | Q25: - | R25: - | S25: - | T25: - | U25: - | V25: - | W25: - | X25: - | Y25: - | Z25: - | AA25: - | AB25: - | AC25: - | AD25: - | AE25: - | AF25: - | AG25: - | AH25: - | AI25: - | AJ25: - | AK25: - | AL25: - | AM25: - | AN25: - | AO25: - | AP25: - | AQ25: - | AR25: - | AS25: - | AT25: - | AU25: - | AV25: - | AW25: - | AX25: - | AY25: - | AZ25: - | BA25: - | BB25: - | BC25: - | BD25: - | BE25: - | BF25: - | BG25: - | BH25: - | BI25: - | BJ25: - | BK25: - | BL25: - | BM25: - | BN25: - | BO25: - | BP25: - | BQ25: - | BR25: - | BS25: - | BT25: - | BU25: - | BV25: - | BW25: - | BX25: - | BY25: - | BZ25: - | CA25: - | CB25: - | CC25: - | CD25: - | CE25: - | CF25: - | CG25: - | CH25: - | CI25: - | CJ25: - | CK25: - | CL25: - | CM25: - | CN25: - | CO25: - | CP25: -
A26: 05:45 - 06:00 | B26: - | C26: - | D26: - | E26: 0 | F26: 2.62 | G26: RTM | H26: - | I26: - | J26: - | K26: - | L26: - | M26: - | N26: - | O26: - | P26: - | Q26: - | R26: - | S26: - | T26: - | U26: - | V26: - | W26: - | X26: - | Y26: - | Z26: - | AA26: - | AB26: - | AC26: - | AD26: - | AE26: - | AF26: - | AG26: - | AH26: - | AI26: - | AJ26: - | AK26: - | AL26: - | AM26: - | AN26: - | AO26: - | AP26: - | AQ26: - | AR26: - | AS26: - | AT26: - | AU26: - | AV26: - | AW26: - | AX26: - | AY26: - | AZ26: - | BA26: - | BB26: - | BC26: - | BD26: - | BE26: - | BF26: - | BG26: - | BH26: - | BI26: - | BJ26: - | BK26: - | BL26: - | BM26: - | BN26: - | BO26: - | BP26: - | BQ26: - | BR26: - | BS26: - | BT26: - | BU26: - | BV26: - | BW26: - | BX26: - | BY26: - | BZ26: - | CA26: - | CB26: - | CC26: - | CD26: - | CE26: - | CF26: - | CG26: - | CH26: - | CI26: - | CJ26: - | CK26: - | CL26: - | CM26: - | CN26: - | CO26: - | CP26: -
A27: 06:00 - 06:15 | B27: - | C27: - | D27: - | E27: 0 | F27: 2.78 | G27: RTM | H27: - | I27: - | J27: - | K27: - | L27: - | M27: - | N27: - | O27: - | P27: - | Q27: - | R27: - | S27: - | T27: - | U27: - | V27: - | W27: - | X27: - | Y27: - | Z27: - | AA27: - | AB27: - | AC27: - | AD27: - | AE27: - | AF27: - | AG27: - | AH27: - | AI27: - | AJ27: - | AK27: - | AL27: - | AM27: - | AN27: - | AO27: - | AP27: - | AQ27: - | AR27: - | AS27: - | AT27: - | AU27: - | AV27: - | AW27: - | AX27: - | AY27: - | AZ27: - | BA27: - | BB27: - | BC27: - | BD27: - | BE27: - | BF27: - | BG27: - | BH27: - | BI27: - | BJ27: - | BK27: - | BL27: - | BM27: - | BN27: - | BO27: - | BP27: - | BQ27: - | BR27: - | BS27: - | BT27: - | BU27: - | BV27: - | BW27: - | BX27: - | BY27: - | BZ27: - | CA27: - | CB27: - | CC27: - | CD27: - | CE27: - | CF27: - | CG27: - | CH27: - | CI27: - | CJ27: - | CK27: - | CL27: - | CM27: - | CN27: - | CO27: - | CP27: -
A28: 06:15 - 06:30 | B28: - | C28: - | D28: - | E28: 0 | F28: 2.6 | G28: RTM | H28: - | I28: - | J28: - | K28: - | L28: - | M28: - | N28: - | O28: - | P28: - | Q28: - | R28: - | S28: - | T28: - | U28: - | V28: - | W28: - | X28: - | Y28: - | Z28: - | AA28: - | AB28: - | AC28: - | AD28: - | AE28: - | AF28: - | AG28: - | AH28: - | AI28: - | AJ28: - | AK28: - | AL28: - | AM28: - | AN28: - | AO28: - | AP28: - | AQ28: - | AR28: - | AS28: - | AT28: - | AU28: - | AV28: - | AW28: - | AX28: - | AY28: - | AZ28: - | BA28: - | BB28: - | BC28: - | BD28: - | BE28: - | BF28: - | BG28: - | BH28: - | BI28: - | BJ28: - | BK28: - | BL28: - | BM28: - | BN28: - | BO28: - | BP28: - | BQ28: - | BR28: - | BS28: - | BT28: - | BU28: - | BV28: - | BW28: - | BX28: - | BY28: - | BZ28: - | CA28: - | CB28: - | CC28: - | CD28: - | CE28: - | CF28: - | CG28: - | CH28: - | CI28: - | CJ28: - | CK28: - | CL28: - | CM28: - | CN28: - | CO28: - | CP28: -
A29: 06:30 - 06:45 | B29: - | C29: - | D29: - | E29: - | F29: - | G29: - | H29: - | I29: - | J29: - | K29: - | L29: - | M29: - | N29: - | O29: - | P29: - | Q29: - | R29: - | S29: - | T29: - | U29: - | V29: - | W29: - | X29: - | Y29: - | Z29: - | AA29: - | AB29: - | AC29: - | AD29: - | AE29: - | AF29: - | AG29: - | AH29: - | AI29: - | AJ29: - | AK29: - | AL29: - | AM29: - | AN29: - | AO29: - | AP29: - | AQ29: - | AR29: - | AS29: - | AT29: - | AU29: - | AV29: - | AW29: - | AX29: - | AY29: - | AZ29: - | BA29: - | BB29: - | BC29: - | BD29: - | BE29: - | BF29: - | BG29: - | BH29: - | BI29: - | BJ29: - | BK29: - | BL29: - | BM29: - | BN29: - | BO29: - | BP29: - | BQ29: - | BR29: - | BS29: - | BT29: - | BU29: - | BV29: - | BW29: - | BX29: - | BY29: - | BZ29: - | CA29: - | CB29: - | CC29: - | CD29: - | CE29: - | CF29: - | CG29: - | CH29: - | CI29: - | CJ29: - | CK29: - | CL29: - | CM29: - | CN29: - | CO29: - | CP29: -
A30: 06:45 - 07:00 | B30: 0 | C30: 2.41 | D30: RTM | E30: 0 | F30: 2.62 | G30: RTM | H30: - | I30: - | J30: - | K30: - | L30: - | M30: - | N30: - | O30: - | P30: - | Q30: - | R30: - | S30: - | T30: - | U30: - | V30: - | W30: 0 | X30: 3.82 | Y30: DAM | Z30: - | AA30: - | AB30: - | AC30: - | AD30: - | AE30: - | AF30: - | AG30: - | AH30: - | AI30: - | AJ30: - | AK30: - | AL30: - | AM30: - | AN30: - | AO30: - | AP30: - | AQ30: - | AR30: - | AS30: - | AT30: - | AU30: - | AV30: - | AW30: - | AX30: - | AY30: - | AZ30: - | BA30: - | BB30: - | BC30: - | BD30: - | BE30: - | BF30: - | BG30: - | BH30: - | BI30: - | BJ30: - | BK30: - | BL30: - | BM30: - | BN30: - | BO30: - | BP30: - | BQ30: - | BR30: - | BS30: - | BT30: - | BU30: - | BV30: - | BW30: - | BX30: - | BY30: - | BZ30: - | CA30: - | CB30: - | CC30: - | CD30: - | CE30: - | CF30: - | CG30: - | CH30: - | CI30: - | CJ30: - | CK30: - | CL30: - | CM30: - | CN30: - | CO30: - | CP30: -
A31: 07:00 - 07:15 | B31: 0 | C31: 2.79 | D31: RTM | E31: 0 | F31: 2.19 | G31: RTM | H31: - | I31: - | J31: - | K31: - | L31: - | M31: - | N31: 0 | O31: 2.4 | P31: RTM | Q31: 0 | R31: 2.52 | S31: RTM | T31: - | U31: - | V31: - | W31: - | X31: - | Y31: - | Z31: - | AA31: - | AB31: - | AC31: - | AD31: - | AE31: - | AF31: 0 | AG31: 2.04 | AH31: RTM | AI31: 0 | AJ31: 3.41 | AK31: DAM | AL31: - | AM31: - | AN31: - | AO31: - | AP31: - | AQ31: - | AR31: - | AS31: - | AT31: - | AU31: - | AV31: - | AW31: - | AX31: - | AY31: - | AZ31: - | BA31: - | BB31: - | BC31: - | BD31: - | BE31: - | BF31: - | BG31: - | BH31: - | BI31: - | BJ31: - | BK31: - | BL31: - | BM31: - | BN31: - | BO31: - | BP31: - | BQ31: - | BR31: - | BS31: - | BT31: - | BU31: - | BV31: - | BW31: - | BX31: - | BY31: - | BZ31: - | CA31: - | CB31: - | CC31: - | CD31: - | CE31: - | CF31: - | CG31: - | CH31: - | CI31: - | CJ31: - | CK31: 0 | CL31: 5 | CM31: DAM | CN31: - | CO31: - | CP31: -
A32: 07:15 - 07:30 | B32: 0 | C32: 2.36 | D32: RTM | E32: 0 | F32: 2.19 | G32: RTM | H32: 0 | I32: 2.36 | J32: RTM | K32: - | L32: - | M32: - | N32: 0 | O32: 2.01 | P32: RTM | Q32: 0 | R32: 2.35 | S32: RTM | T32: - | U32: - | V32: - | W32: 0 | X32: 3.28 | Y32: DAM | Z32: - | AA32: - | AB32: - | AC32: - | AD32: - | AE32: - | AF32: 0 | AG32: 2.19 | AH32: RTM | AI32: 0 | AJ32: 3.23 | AK32: DAM | AL32: - | AM32: - | AN32: - | AO32: - | AP32: - | AQ32: - | AR32: - | AS32: - | AT32: - | AU32: - | AV32: - | AW32: - | AX32: - | AY32: - | AZ32: - | BA32: - | BB32: - | BC32: - | BD32: - | BE32: - | BF32: - | BG32: - | BH32: - | BI32: - | BJ32: - | BK32: - | BL32: - | BM32: - | BN32: - | BO32: - | BP32: - | BQ32: - | BR32: - | BS32: - | BT32: - | BU32: - | BV32: - | BW32: - | BX32: - | BY32: - | BZ32: - | CA32: - | CB32: - | CC32: - | CD32: - | CE32: - | CF32: - | CG32: - | CH32: 0 | CI32: 2.54 | CJ32: RTM | CK32: 0 | CL32: 4.08 | CM32: DAM | CN32: - | CO32: - | CP32: -
A33: 07:30 - 07:45 | B33: 0 | C33: 2.36 | D33: RTM | E33: 0 | F33: 2.02 | G33: RTM | H33: 0 | I33: 2.75 | J33: RTM | K33: 0 | L33: 3 | M33: DAM | N33: 0.28 | O33: 1 | P33: RTM | Q33: 0 | R33: 2.54 | S33: RTM | T33: 0 | U33: 2.9 | V33: DAM | W33: 0 | X33: 3 | Y33: DAM | Z33: 0 | AA33: 3.04 | AB33: RTM | AC33: 0 | AD33: 2.62 | AE33: RTM | AF33: 0 | AG33: 2.4 | AH33: RTM | AI33: 0 | AJ33: 2.53 | AK33: DAM | AL33: - | AM33: - | AN33: - | AO33: - | AP33: - | AQ33: - | AR33: - | AS33: - | AT33: - | AU33: - | AV33: - | AW33: - | AX33: - | AY33: - | AZ33: - | BA33: - | BB33: - | BC33: - | BD33: - | BE33: - | BF33: - | BG33: - | BH33: - | BI33: - | BJ33: - | BK33: - | BL33: - | BM33: - | BN33: - | BO33: - | BP33: 0 | BQ33: 2.54 | BR33: RTM | BS33: - | BT33: - | BU33: - | BV33: - | BW33: - | BX33: - | BY33: - | BZ33: - | CA33: - | CB33: - | CC33: - | CD33: - | CE33: 0 | CF33: 2.51 | CG33: RTM | CH33: 0 | CI33: 2.05 | CJ33: RTM | CK33: 0 | CL33: 3.54 | CM33: DAM | CN33: 0 | CO33: 2.5 | CP33: RTM
A34: 07:45 - 08:00 | B34: 0 | C34: 2.02 | D34: RTM | E34: 0 | F34: 2.31 | G34: RTM | H34: 0 | I34: 2.55 | J34: RTM | K34: 0 | L34: 2.52 | M34: DAM | N34: 0.28 | O34: 0.19 | P34: RTM | Q34: 0 | R34: 2.52 | S34: RTM | T34: 0 | U34: 2.56 | V34: DAM | W34: 0 | X34: 2.68 | Y34: DAM | Z34: 0 | AA34: 2.64 | AB34: RTM | AC34: 0 | AD34: 2.4 | AE34: RTM | AF34: 0 | AG34: 2.03 | AH34: RTM | AI34: 0 | AJ34: 2.33 | AK34: DAM | AL34: 0 | AM34: 2.19 | AN34: RTM | AO34: 0 | AP34: 3.54 | AQ34: DAM | AR34: - | AS34: - | AT34: - | AU34: - | AV34: - | AW34: - | AX34: - | AY34: - | AZ34: - | BA34: - | BB34: - | BC34: - | BD34: 0 | BE34: 2.65 | BF34: RTM | BG34: 0 | BH34: 2 | BI34: RTM | BJ34: 0.28 | BK34: 1.52 | BL34: RTM | BM34: - | BN34: - | BO34: - | BP34: 0.28 | BQ34: 1.8 | BR34: RTM | BS34: - | BT34: - | BU34: - | BV34: - | BW34: - | BX34: - | BY34: 0 | BZ34: 3.26 | CA34: DAM | CB34: 0.28 | CC34: 1.62 | CD34: RTM | CE34: 0.28 | CF34: 0.83 | CG34: RTM | CH34: 0.28 | CI34: 0.4 | CJ34: RTM | CK34: 0 | CL34: 3.36 | CM34: DAM | CN34: 0.28 | CO34: 0.02 | CP34: RTM
A35: 08:00 - 08:15 | B35: 0 | C35: 2.05 | D35: RTM | E35: 0 | F35: 2.01 | G35: RTM | H35: 0 | I35: 2.66 | J35: RTM | K35: 0.28 | L35: 1.92 | M35: DAM | N35: 0.28 | O35: 1.14 | P35: RTM | Q35: 0 | R35: 2.54 | S35: RTM | T35: 0 | U35: 2.46 | V35: DAM | W35: 0 | X35: 2.43 | Y35: DAM | Z35: 0 | AA35: 2.56 | AB35: RTM | AC35: 0 | AD35: 2.54 | AE35: RTM | AF35: 0.28 | AG35: 1.81 | AH35: RTM | AI35: 0.28 | AJ35: 1.87 | AK35: DAM | AL35: 0 | AM35: 2.42 | AN35: RTM | AO35: 0 | AP35: 3.2 | AQ35: DAM | AR35: - | AS35: - | AT35: - | AU35: - | AV35: - | AW35: - | AX35: - | AY35: - | AZ35: - | BA35: 0 | BB35: 2.71 | BC35: RTM | BD35: 0.28 | BE35: 0.5 | BF35: RTM | BG35: 0 | BH35: 2.39 | BI35: RTM | BJ35: 0 | BK35: 2.33 | BL35: RTM | BM35: - | BN35: - | BO35: - | BP35: 0 | BQ35: 2.52 | BR35: RTM | BS35: - | BT35: - | BU35: - | BV35: - | BW35: - | BX35: - | BY35: 0 | BZ35: 2.7 | CA35: DAM | CB35: 0.28 | CC35: 2 | CD35: RTM | CE35: 0.28 | CF35: 1.44 | CG35: RTM | CH35: 0 | CI35: 2.07 | CJ35: RTM | CK35: 0 | CL35: 2.53 | CM35: DAM | CN35: 0 | CO35: 2.07 | CP35: RTM
A36: 08:15 - 08:30 | B36: 0.28 | C36: 2 | D36: RTM | E36: 0.28 | F36: 1.02 | G36: RTM | H36: 0 | I36: 2.75 | J36: RTM | K36: 0.28 | L36: 1.39 | M36: DAM | N36: 0.28 | O36: 1.28 | P36: RTM | Q36: 0 | R36: 2.52 | S36: RTM | T36: 0 | U36: 2.46 | V36: DAM | W36: 0 | X36: 2.38 | Y36: DAM | Z36: 0 | AA36: 2.52 | AB36: RTM | AC36: 0 | AD36: 2.5 | AE36: RTM | AF36: 0.28 | AG36: 1.65 | AH36: RTM | AI36: 0.28 | AJ36: 1.44 | AK36: DAM | AL36: 0 | AM36: 2.56 | AN36: RTM | AO36: 0 | AP36: 2.56 | AQ36: DAM | AR36: 0 | AS36: 2.7 | AT36: DAM | AU36: - | AV36: - | AW36: - | AX36: - | AY36: - | AZ36: - | BA36: 0 | BB36: 2.5 | BC36: RTM | BD36: 0.28 | BE36: 2 | BF36: RTM | BG36: - | BH36: - | BI36: - | BJ36: - | BK36: - | BL36: - | BM36: - | BN36: - | BO36: - | BP36: - | BQ36: - | BR36: - | BS36: - | BT36: - | BU36: - | BV36: - | BW36: - | BX36: - | BY36: 0 | BZ36: 2.2 | CA36: DAM | CB36: 0 | CC36: 2.05 | CD36: RTM | CE36: 0.28 | CF36: 1.44 | CG36: RTM | CH36: 0 | CI36: 2.46 | CJ36: RTM | CK36: 0 | CL36: 2.19 | CM36: DAM | CN36: 0 | CO36: 2.07 | CP36: RTM
A37: 08:30 - 08:45 | B37: 0 | C37: 2.02 | D37: RTM | E37: 0.28 | F37: 0.4 | G37: RTM | H37: 0 | I37: 2.36 | J37: RTM | K37: 0.28 | L37: 1.21 | M37: DAM | N37: 0.28 | O37: 1.56 | P37: RTM | Q37: 0.28 | R37: 2.01 | S37: RTM | T37: 0 | U37: 2.15 | V37: DAM | W37: 0.28 | X37: 2 | Y37: DAM | Z37: 0 | AA37: 2.46 | AB37: RTM | AC37: 0 | AD37: 2.19 | AE37: RTM | AF37: 0.28 | AG37: 1.62 | AH37: RTM | AI37: 0.28 | AJ37: 1.5 | AK37: DAM | AL37: 0.28 | AM37: 0.75 | AN37: RTM | AO37: 0 | AP37: 2.52 | AQ37: DAM | AR37: 0 | AS37: 2.52 | AT37: DAM | AU37: - | AV37: - | AW37: - | AX37: - | AY37: - | AZ37: - | BA37: - | BB37: - | BC37: - | BD37: 0 | BE37: 2.5 | BF37: RTM | BG37: - | BH37: - | BI37: - | BJ37: - | BK37: - | BL37: - | BM37: - | BN37: - | BO37: - | BP37: - | BQ37: - | BR37: - | BS37: - | BT37: - | BU37: - | BV37: - | BW37: - | BX37: - | BY37: 0 | BZ37: 2.12 | CA37: DAM | CB37: 0.28 | CC37: 2 | CD37: RTM | CE37: 0 | CF37: 2.48 | CG37: RTM | CH37: 0 | CI37: 2.86 | CJ37: RTM | CK37: 0 | CL37: 2.04 | CM37: DAM | CN37: 0 | CO37: 2.82 | CP37: RTM
A38: 08:45 - 09:00 | B38: 0.28 | C38: 2.01 | D38: RTM | E38: 0.28 | F38: 0.1 | G38: RTM | H38: 0 | I38: 2.19 | J38: RTM | K38: 0.28 | L38: 1.1 | M38: DAM | N38: 0.28 | O38: 0.1 | P38: RTM | Q38: 0.28 | R38: 1.55 | S38: RTM | T38: 0.28 | U38: 1.95 | V38: DAM | W38: 0.28 | X38: 1.9 | Y38: DAM | Z38: 0 | AA38: 2.42 | AB38: RTM | AC38: 0 | AD38: 2.19 | AE38: RTM | AF38: 0.28 | AG38: 1.62 | AH38: RTM | AI38: 0.28 | AJ38: 1.17 | AK38: DAM | AL38: 0 | AM38: 2.4 | AN38: RTM | AO38: 0 | AP38: 2.38 | AQ38: DAM | AR38: 0 | AS38: 2.32 | AT38: DAM | AU38: - | AV38: - | AW38: - | AX38: - | AY38: - | AZ38: - | BA38: - | BB38: - | BC38: - | BD38: 0 | BE38: 2.52 | BF38: RTM | BG38: - | BH38: - | BI38: - | BJ38: - | BK38: - | BL38: - | BM38: 0 | BN38: 2.86 | BO38: RTM | BP38: - | BQ38: - | BR38: - | BS38: 0 | BT38: 3 | BU38: RTM | BV38: 0 | BW38: 2.67 | BX38: DAM | BY38: 0.28 | BZ38: 1.96 | CA38: DAM | CB38: 0.28 | CC38: 1.55 | CD38: RTM | CE38: 0 | CF38: 2.1 | CG38: RTM | CH38: 0 | CI38: 2.8 | CJ38: RTM | CK38: 0.28 | CL38: 2 | CM38: DAM | CN38: 0 | CO38: 2.79 | CP38: RTM
A39: 09:00 - 09:15 | B39: 0.28 | C39: 1.8 | D39: RTM | E39: 0.28 | F39: 0.05 | G39: RTM | H39: 0 | I39: 2.05 | J39: RTM | K39: 0.28 | L39: 0.5 | M39: DAM | N39: 0.28 | O39: 0.02 | P39: RTM | Q39: 0.28 | R39: 1.54 | S39: RTM | T39: 0.28 | U39: 1.5 | V39: DAM | W39: 0.28 | X39: 1.4 | Y39: DAM | Z39: 0 | AA39: 2.1 | AB39: RTM | AC39: 0.28 | AD39: 1.95 | AE39: RTM | AF39: 0.28 | AG39: 0.03 | AH39: RTM | AI39: 0.28 | AJ39: 0.66 | AK39: DAM | AL39: 0 | AM39: 2.1 | AN39: RTM | AO39: 0 | AP39: 2.32 | AQ39: DAM | AR39: 0 | AS39: 2.29 | AT39: DAM | AU39: - | AV39: - | AW39: - | AX39: - | AY39: - | AZ39: - | BA39: 0.28 | BB39: 2 | BC39: RTM | BD39: 0 | BE39: 2.56 | BF39: RTM | BG39: - | BH39: - | BI39: - | BJ39: 0 | BK39: 3.03 | BL39: RTM | BM39: 0 | BN39: 2.88 | BO39: RTM | BP39: - | BQ39: - | BR39: - | BS39: 0 | BT39: 2.75 | BU39: RTM | BV39: 0 | BW39: 2.54 | BX39: DAM | BY39: 0.28 | BZ39: 1.87 | CA39: DAM | CB39: 0.28 | CC39: 1.56 | CD39: RTM | CE39: 0 | CF39: 2.12 | CG39: RTM | CH39: 0 | CI39: 3.26 | CJ39: RTM | CK39: 0.28 | CL39: 1.93 | CM39: DAM | CN39: 0 | CO39: 2.86 | CP39: RTM
A40: 09:15 - 09:30 | B40: 0.28 | C40: 1.79 | D40: RTM | E40: 0.28 | F40: 0.4 | G40: RTM | H40: 0.28 | I40: 1.97 | J40: RTM | K40: 0.28 | L40: 0.5 | M40: DAM | N40: 0.28 | O40: 0.02 | P40: RTM | Q40: 0.28 | R40: 0.48 | S40: RTM | T40: 0.28 | U40: 1.4 | V40: DAM | W40: 0.28 | X40: 1.36 | Y40: DAM | Z40: 0 | AA40: 2.1 | AB40: RTM | AC40: 0.28 | AD40: 1.62 | AE40: RTM | AF40: 0.28 | AG40: 0.02 | AH40: RTM | AI40: 0.28 | AJ40: 0.35 | AK40: DAM | AL40: 0 | AM40: 2.13 | AN40: RTM | AO40: 0 | AP40: 2.29 | AQ40: DAM | AR40: 0 | AS40: 2.29 | AT40: DAM | AU40: - | AV40: - | AW40: - | AX40: - | AY40: - | AZ40: - | BA40: 0.28 | BB40: 1.62 | BC40: RTM | BD40: 0 | BE40: 2.5 | BF40: RTM | BG40: - | BH40: - | BI40: - | BJ40: 0 | BK40: 2.76 | BL40: RTM | BM40: 0 | BN40: 2.86 | BO40: RTM | BP40: 0 | BQ40: 2.6 | BR40: RTM | BS40: 0 | BT40: 2.05 | BU40: RTM | BV40: 0 | BW40: 2.48 | BX40: DAM | BY40: 0.28 | BZ40: 1.84 | CA40: DAM | CB40: 0.28 | CC40: 1.56 | CD40: RTM | CE40: 0.28 | CF40: 1.55 | CG40: RTM | CH40: 0 | CI40: 2.7 | CJ40: RTM | CK40: 0.28 | CL40: 1.84 | CM40: DAM | CN40: 0 | CO40: 2.55 | CP40: RTM
...
